Workbook

Sheet Input
A1: CAGE | B1: CFNM | C1: CLNM | D1: TGID | E1: CRAT | F1: COPS
A2: 54 | B2: Troy | C2: Calhoun | D2: 1 | E2: 91 | F2: 0
A3: 42 | B3: Mike | C3: Thiessen | D3: 1 | E3: 91 | F3: 1
A4: 38 | B4: John | C4: Rudzinski | D4: 1 | E4: 91 | F4: 2
A5: 40 | B5: Tom | C5: Arth | D5: 2 | E5: 36 | F5: 0
A6: 36 | B6: Tommy | C6: Zagorski | D6: 2 | E6: 36 | F6: 1
A7: 29 | B7: Matt | C7: Feeney | D7: 2 | E7: 36 | F7: 2
A8: 68 | B8: Nick | C8: Saban | D8: 3 | E8: 99 | F8: 0
A9: 51 | B9: Bill | C9: O'Brien | D9: 3 | E9: 99 | F9: 1
A10: 37 | B10: Pete | C10: Golding | D10: 3 | E10: 99 | F10: 2
A11: 45 | B11: Jedd | C11: Fisch | D11: 4 | E11: 14 | F11: 0
A12: 42 | B12: Brennan | C12: Carroll | D12: 4 | E12: 14 | F12: 1
A13: 66 | B13: Don | C13: Brown | D13: 4 | E13: 14 | F13: 2
... A394: 52 | B394: Corey | C394: Batoon | D394: 235 | E394: 48 | F394: 2
A395: 35 | C395: SJSU Coach | D395: 610 | E395: 24 | F395: 0
A396: 34 | C396: NIU Coach | D396: 611 | E396: 25 | F396: 0
A397: 45 | C397: NMSU Coach | D397: 612 | E397: 78 | F397: 0
A398: 36 | C398: WKU Coach | D398: 613 | E398: 58 | F398: 0
A399: 35 | C399: Tul Coach | D399: 614 | E399: 54 | F399: 0
A400: 27 | C400: SJSU Coach | D400: 615 | E400: 78 | F400: 0
A401: 36 | C401: NIU Coach | D401: 616 | E401: 75 | F401: 0
A402: 42 | C402: NMSU Coach | D402: 617 | E402: 48 | F402: 0
A403: 43 | C403: WKU Coach | D403: 618 | E403: 51 | F403: 0
A404: 27 | C404: Tul Coach | D404: 619 | E404: 53 | F404: 0

Sheet Output_Pre
A1: TEAM | B1: NAME | C1: POSITION | D1: AGE | E1: OVR | F1: Knockdown | G1: Overall Stars
A2: =VLOOKUP(Input!D2,Converter!K:M,3,FALSE) -> Air Force | B2: =Input!B2&" "&Input!C2 -> Troy Calhoun | C2: =VLOOKUP(Input!F2,Converter!P$2:R$23,3,FALSE) -> HC | D2: =Input!A2+1 -> 55 | E2: =Input!E2 -> 91 | F2: =IF(C2<>"HC",E2*0.7,E2) -> 91 | G2: =ROUND(E2/11,0) -> 8
A3: =VLOOKUP(Input!D3,Converter!K:M,3,FALSE) -> Air Force | B3: =Input!B3&" "&Input!C3 -> Mike Thiessen | C3: =VLOOKUP(Input!F3,Converter!P$2:R$23,3,FALSE) -> OC | D3: =Input!A3+1 -> 43 | E3: =Input!E3 -> 91 | F3: =IF(C3<>"HC",E3*0.7,E3) -> 63.7 | G3: =ROUND(E3/11,0) -> 8
A4: =VLOOKUP(Input!D4,Converter!K:M,3,FALSE) -> Air Force | B4: =Input!B4&" "&Input!C4 -> John Rudzinski | C4: =VLOOKUP(Input!F4,Converter!P$2:R$23,3,FALSE) -> DC | D4: =Input!A4+1 -> 39 | E4: =Input!E4 -> 91 | F4: =IF(C4<>"HC",E4*0.7,E4) -> 63.7 | G4: =ROUND(E4/11,0) -> 8
A5: =VLOOKUP(Input!D5,Converter!K:M,3,FALSE) -> Akron | B5: =Input!B5&" "&Input!C5 -> Tom Arth | C5: =VLOOKUP(Input!F5,Converter!P$2:R$23,3,FALSE) -> HC | D5: =Input!A5+1 -> 41 | E5: =Input!E5 -> 36 | F5: =IF(C5<>"HC",E5*0.7,E5) -> 36 | G5: =ROUND(E5/11,0) -> 3
A6: =VLOOKUP(Input!D6,Converter!K:M,3,FALSE) -> Akron | B6: =Input!B6&" "&Input!C6 -> Tommy Zagorski | C6: =VLOOKUP(Input!F6,Converter!P$2:R$23,3,FALSE) -> OC | D6: =Input!A6+1 -> 37 | E6: =Input!E6 -> 36 | F6: =IF(C6<>"HC",E6*0.7,E6) -> 25.2 | G6: =ROUND(E6/11,0) -> 3
A7: =VLOOKUP(Input!D7,Converter!K:M,3,FALSE) -> Akron | B7: =Input!B7&" "&Input!C7 -> Matt Feeney | C7: =VLOOKUP(Input!F7,Converter!P$2:R$23,3,FALSE) -> DC | D7: =Input!A7+1 -> 30 | E7: =Input!E7 -> 36 | F7: =IF(C7<>"HC",E7*0.7,E7) -> 25.2 | G7: =ROUND(E7/11,0) -> 3
A8: =VLOOKUP(Input!D8,Converter!K:M,3,FALSE) -> Alabama | B8: =Input!B8&" "&Input!C8 -> Nick Saban | C8: =VLOOKUP(Input!F8,Converter!P$2:R$23,3,FALSE) -> HC | D8: =Input!A8+1 -> 69 | E8: =Input!E8 -> 99 | F8: =IF(C8<>"HC",E8*0.7,E8) -> 99 | G8: =ROUND(E8/11,0) -> 9
A9: =VLOOKUP(Input!D9,Converter!K:M,3,FALSE) -> Alabama | B9: =Input!B9&" "&Input!C9 -> Bill O'Brien | C9: =VLOOKUP(Input!F9,Converter!P$2:R$23,3,FALSE) -> OC | D9: =Input!A9+1 -> 52 | E9: =Input!E9 -> 99 | F9: =IF(C9<>"HC",E9*0.7,E9) -> 69.3 | G9: =ROUND(E9/11,0) -> 9
A10: =VLOOKUP(Input!D10,Converter!K:M,3,FALSE) -> Alabama | B10: =Input!B10&" "&Input!C10 -> Pete Golding | C10: =VLOOKUP(Input!F10,Converter!P$2:R$23,3,FALSE) -> DC | D10: =Input!A10+1 -> 38 | E10: =Input!E10 -> 99 | F10: =IF(C10<>"HC",E10*0.7,E10) -> 69.3 | G10: =ROUND(E10/11,0) -> 9
A11: =VLOOKUP(Input!D11,Converter!K:M,3,FALSE) -> Arizona | B11: =Input!B11&" "&Input!C11 -> Jedd Fisch | C11: =VLOOKUP(Input!F11,Converter!P$2:R$23,3,FALSE) -> HC | D11: =Input!A11+1 -> 46 | E11: =Input!E11 -> 14 | F11: =IF(C11<>"HC",E11*0.7,E11) -> 14 | G11: =ROUND(E11/11,0) -> 1
A12: =VLOOKUP(Input!D12,Converter!K:M,3,FALSE) -> Arizona | B12: =Input!B12&" "&Input!C12 -> Brennan Carroll | C12: =VLOOKUP(Input!F12,Converter!P$2:R$23,3,FALSE) -> OC | D12: =Input!A12+1 -> 43 | E12: =Input!E12 -> 14 | F12: =IF(C12<>"HC",E12*0.7,E12) -> 9.8 | G12: =ROUND(E12/11,0) -> 1
A13: =VLOOKUP(Input!D13,Converter!K:M,3,FALSE) -> Arizona | B13: =Input!B13&" "&Input!C13 -> Don Brown | C13: =VLOOKUP(Input!F13,Converter!P$2:R$23,3,FALSE) -> DC | D13: =Input!A13+1 -> 67 | E13: =Input!E13 -> 14 | F13: =IF(C13<>"HC",E13*0.7,E13) -> 9.8 | G13: =ROUND(E13/11,0) -> 1
... A8695: =VLOOKUP(Input!D8695,Converter!K:M,3,FALSE) -> #N/A | B8695: =Input!B8695&" "&Input!C8695 | C8695: =VLOOKUP(Input!F8695,Converter!P$2:R$23,3,FALSE) -> HC | D8695: =Input!A8695+1 -> 1 | E8695: =Input!E8695 -> 0 | F8695: =IF(C8695<>"HC",E8695*0.7,E8695) -> 0 | G8695: =ROUND(E8695/11,0) -> 0

Sheet Output
A1: =Output_Pre!A1 -> TEAM | B1: =Output_Pre!B1 -> NAME | C1: =Output_Pre!C1 -> POSITION | D1: STARS
A2: =Output_Pre!A2 -> Air Force | B2: =Output_Pre!B2 -> Troy Calhoun | C2: =Output_Pre!C2 -> HC | D2: =Output_Pre!G2 -> 8
A3: =Output_Pre!A3 -> Air Force | B3: =Output_Pre!B3 -> Mike Thiessen | C3: =Output_Pre!C3 -> OC | D3: =Output_Pre!G3 -> 8
A4: =Output_Pre!A4 -> Air Force | B4: =Output_Pre!B4 -> John Rudzinski | C4: =Output_Pre!C4 -> DC | D4: =Output_Pre!G4 -> 8
A5: =Output_Pre!A5 -> Akron | B5: =Output_Pre!B5 -> Tom Arth | C5: =Output_Pre!C5 -> HC | D5: =Output_Pre!G5 -> 3
A6: =Output_Pre!A6 -> Akron | B6: =Output_Pre!B6 -> Tommy Zagorski | C6: =Output_Pre!C6 -> OC | D6: =Output_Pre!G6 -> 3
A7: =Output_Pre!A7 -> Akron | B7: =Output_Pre!B7 -> Matt Feeney | C7: =Output_Pre!C7 -> DC | D7: =Output_Pre!G7 -> 3
A8: =Output_Pre!A8 -> Alabama | B8: =Output_Pre!B8 -> Nick Saban | C8: =Output_Pre!C8 -> HC | D8: =Output_Pre!G8 -> 9
A9: =Output_Pre!A9 -> Alabama | B9: =Output_Pre!B9 -> Bill O'Brien | C9: =Output_Pre!C9 -> OC | D9: =Output_Pre!G9 -> 9
A10: =Output_Pre!A10 -> Alabama | B10: =Output_Pre!B10 -> Pete Golding | C10: =Output_Pre!C10 -> DC | D10: =Output_Pre!G10 -> 9
A11: =Output_Pre!A11 -> Arizona | B11: =Output_Pre!B11 -> Jedd Fisch | C11: =Output_Pre!C11 -> HC | D11: =Output_Pre!G11 -> 1
A12: =Output_Pre!A12 -> Arizona | B12: =Output_Pre!B12 -> Brennan Carroll | C12: =Output_Pre!C12 -> OC | D12: =Output_Pre!G12 -> 1
A13: =Output_Pre!A13 -> Arizona | B13: =Output_Pre!B13 -> Don Brown | C13: =Output_Pre!C13 -> DC | D13: =Output_Pre!G13 -> 1
... A1864: =Output_Pre!A1864 -> #N/A | B1864: =Output_Pre!B1864 | C1864: =Output_Pre!C1864 -> HC | D1864: =Output_Pre!G1864 -> 0
A1865: =Output_Pre!A8282 -> #N/A | B1865: =Output_Pre!B8282 | C1865: =Output_Pre!C8282 -> HC | D1865: =Output_Pre!G1865 -> 0
A1866: =Output_Pre!A8283 -> #N/A | B1866: =Output_Pre!B8283 | C1866: =Output_Pre!C8283 -> HC | D1866: =Output_Pre!G1866 -> 0
A1867: =Output_Pre!A8284 -> #N/A | B1867: =Output_Pre!B8284 | C1867: =Output_Pre!C8284 -> HC | D1867: =Output_Pre!G1867 -> 0
A1868: =Output_Pre!A8285 -> #N/A | B1868: =Output_Pre!B8285 | C1868: =Output_Pre!C8285 -> HC | D1868: =Output_Pre!G1868 -> 0
A1869: =Output_Pre!A8286 -> #N/A | B1869: =Output_Pre!B8286 | C1869: =Output_Pre!C8286 -> HC | D1869: =Output_Pre!G1869 -> 0
A1870: =Output_Pre!A8287 -> #N/A | B1870: =Output_Pre!B8287 | C1870: =Output_Pre!C8287 -> HC | D1870: =Output_Pre!G1870 -> 0
A1871: =Output_Pre!A8288 -> #N/A | B1871: =Output_Pre!B8288 | C1871: =Output_Pre!C8288 -> HC | D1871: =Output_Pre!G1871 -> 0
A1872: =Output_Pre!A8289 -> #N/A | B1872: =Output_Pre!B8289 | C1872: =Output_Pre!C8289 -> HC | D1872: =Output_Pre!G1872 -> 0
A1873: =Output_Pre!A8290 -> #N/A | B1873: =Output_Pre!B8290 | C1873: =Output_Pre!C8290 -> HC | D1873: =Output_Pre!G1873 -> 0
A1874: =Output_Pre!A8291 -> #N/A | B1874: =Output_Pre!B8291 | C1874: =Output_Pre!C8291 -> HC | D1874: =Output_Pre!G1874 -> 0
A1875: =Output_Pre!A8292 -> #N/A | B1875: =Output_Pre!B8292 | C1875: =Output_Pre!C8292 -> HC | D1875: =Output_Pre!G1875 -> 0
A1876: =Output_Pre!A8293 -> #N/A | B1876: =Output_Pre!B8293 | C1876: =Output_Pre!C8293 -> HC | D1876: =Output_Pre!G1876 -> 0
... A2002: =Output_Pre!A8419 -> #N/A | B2002: =Output_Pre!B8419 | C2002: =Output_Pre!C8419 -> HC | D2002: =Output_Pre!G2002 -> 0
A2003: =Output_Pre!A1865 -> #N/A | B2003: =Output_Pre!B1865 | C2003: =Output_Pre!C1865 -> HC | D2003: =Output_Pre!G2003 -> 0
A2004: =Output_Pre!A1866 -> #N/A | B2004: =Output_Pre!B1866 | C2004: =Output_Pre!C1866 -> HC | D2004: =Output_Pre!G2004 -> 0
A2005: =Output_Pre!A1867 -> #N/A | B2005: =Output_Pre!B1867 | C2005: =Output_Pre!C1867 -> HC | D2005: =Output_Pre!G2005 -> 0
A2006: =Output_Pre!A1868 -> #N/A | B2006: =Output_Pre!B1868 | C2006: =Output_Pre!C1868 -> HC | D2006: =Output_Pre!G2006 -> 0
A2007: =Output_Pre!A1869 -> #N/A | B2007: =Output_Pre!B1869 | C2007: =Output_Pre!C1869 -> HC | D2007: =Output_Pre!G2007 -> 0
A2008: =Output_Pre!A1870 -> #N/A | B2008: =Output_Pre!B1870 | C2008: =Output_Pre!C1870 -> HC | D2008: =Output_Pre!G2008 -> 0
A2009: =Output_Pre!A1871 -> #N/A | B2009: =Output_Pre!B1871 | C2009: =Output_Pre!C1871 -> HC | D2009: =Output_Pre!G2009 -> 0
A2010: =Output_Pre!A1872 -> #N/A | B2010: =Output_Pre!B1872 | C2010: =Output_Pre!C1872 -> HC | D2010: =Output_Pre!G2010 -> 0
A2011: =Output_Pre!A1873 -> #N/A | B2011: =Output_Pre!B1873 | C2011: =Output_Pre!C1873 -> HC | D2011: =Output_Pre!G2011 -> 0
A2012: =Output_Pre!A1874 -> #N/A | B2012: =Output_Pre!B1874 | C2012: =Output_Pre!C1874 -> HC | D2012: =Output_Pre!G2012 -> 0
A2013: =Output_Pre!A1875 -> #N/A | B2013: =Output_Pre!B1875 | C2013: =Output_Pre!C1875 -> HC | D2013: =Output_Pre!G2013 -> 0
A2014: =Output_Pre!A1876 -> #N/A | B2014: =Output_Pre!B1876 | C2014: =Output_Pre!C1876 -> HC | D2014: =Output_Pre!G2014 -> 0
... A2416: =Output_Pre!A2278 -> #N/A | B2416: =Output_Pre!B2278 | C2416: =Output_Pre!C2278 -> HC | D2416: =Output_Pre!G2416 -> 0
...

Sheet Converter
A1: Positions | B1: New Position | D1: Year Name | E1: Year | G1: Rating | H1: Stars | J1: Team Name ID Numbers
A2: QB | B2: QB | D2: Freshman (RS) | E2: 1 | G2: 98 | H2: 5 | J2: TDNA | K2: Team ID? | L2: Roster | M2: TDNA | N2: Team ID? | P2: PPOS | Q2: PDST
A3: HB | B3: RB | D3: Freshman | E3: 1 | G3: 97 | H3: 5 | J3: Air Force | K3: 1 | L3: =K3*70 -> 70 | M3: Air Force | N3: 1 | P3: 0 | Q3: HC | R3: HC
A4: FB | B4: RB | D4: Sophomore | E4: 2 | G4: 96 | H4: 5 | J4: Akron | K4: 2 | L4: =K4*70 -> 140 | M4: Akron | N4: 2 | P4: 1 | Q4: OC | R4: OC
A5: WR | B5: WR | D5: Junior | E5: 3 | G5: 95 | H5: 5 | J5: Alabama | K5: 3 | L5: =K5*70 -> 210 | M5: Alabama | N5: 3 | P5: 2 | Q5: DC | R5: DC
A6: TE | B6: TE | D6: Senior | E6: 4 | G6: 94 | H6: 5 | J6: Arizona | K6: 4 | L6: =K6*70 -> 280 | M6: Arizona | N6: 4 | P6: 3 | Q6: WR | R6: WR
A7: LT | B7: OL | G7: 93 | H7: 5 | J7: Arizona State | K7: 5 | L7: =K7*70 -> 350 | M7: Arizona State | N7: 5 | P7: 4 | Q7: TE | R7: TE
A8: LG | B8: OL | G8: 92 | H8: 5 | J8: Arkansas | K8: 6 | L8: =K8*70 -> 420 | M8: Arkansas | N8: 6 | P8: 5 | Q8: LT | R8: OL
A9: C | B9: OL | G9: 91 | H9: 5 | J9: Arkansas State | K9: 7 | L9: =K9*70 -> 490 | M9: Arkansas State | N9: 7 | P9: 6 | Q9: LG | R9: OL
A10: RG | B10: OL | G10: 90 | H10: 5 | J10: Army | K10: 8 | L10: =K10*70 -> 560 | M10: Army | N10: 8 | P10: 7 | Q10: C | R10: OL
A11: RT | B11: OL | G11: 89 | H11: 4 | J11: Auburn | K11: 9 | L11: =K11*70 -> 630 | M11: Auburn | N11: 9 | P11: 8 | Q11: RG | R11: OL
A12: LE | B12: DL | G12: 88 | H12: 4 | J12: Ball State | K12: 10 | L12: =K12*70 -> 700 | M12: Ball State | N12: 10 | P12: 9 | Q12: RT | R12: OL
A13: DT | B13: DL | G13: 87 | H13: 4 | J13: Baylor | K13: 11 | L13: =K13*70 -> 770 | M13: Baylor | N13: 11 | P13: 10 | Q13: LE | R13: DL
A14: RE | B14: DL | G14: 86 | H14: 4 | J14: Boise State | K14: 12 | L14: =K14*70 -> 840 | M14: Boise State | N14: 12 | P14: 11 | Q14: RE | R14: DL
A15: OLB | B15: LB | G15: 85 | H15: 4 | J15: Boston College | K15: 13 | L15: =K15*70 -> 910 | M15: Boston College | N15: 13 | P15: 12 | Q15: DT | R15: DL
A16: MLB | B16: LB | G16: 84 | H16: 4 | J16: Bowling Green | K16: 14 | L16: =K16*70 -> 980 | M16: Bowling Green | N16: 14 | P16: 13 | Q16: OLB | R16: LB
A17: CB | B17: CB | G17: 83 | H17: 4 | J17: Buffalo | K17: 15 | L17: =K17*70 -> 1050 | M17: Buffalo | N17: 15 | P17: 14 | Q17: MLB | R17: LB
A18: SS | B18: S | G18: 82 | H18: 4 | J18: BYU | K18: 16 | L18: =K18*70 -> 1120 | M18: BYU | N18: 16 | P18: 15 | Q18: OLB | R18: LB
... A21: P | B21: K | G21: 79 | H21: 3 | J21: Central Michigan | K21: 19 | L21: =K21*70 -> 1330 | M21: Central Michigan | N21: 19 | P21: 18 | Q21: SS | R21: S
G22: 78 | H22: 3 | J22: Cincinnati | K22: 20 | L22: =K22*70 -> 1400 | M22: Cincinnati | N22: 20 | P22: 19 | Q22: K | R22: K
G23: 77 | H23: 3 | J23: Clemson | K23: 21 | L23: =K23*70 -> 1470 | M23: Clemson | N23: 21 | P23: 20 | Q23: P | R23: K
G24: 76 | H24: 2 | J24: Colorado | K24: 22 | L24: =K24*70 -> 1540 | M24: Colorado | N24: 22
G25: 75 | H25: 2 | J25: Colorado State | K25: 23 | L25: =K25*70 -> 1610 | M25: Colorado State | N25: 23
G26: 74 | H26: 2 | J26: Duke | K26: 24 | L26: =K26*70 -> 1680 | M26: Duke | N26: 24 | P26: PYEA | Q26: Year
G27: 73 | H27: 2 | J27: ECU | K27: 25 | L27: =K27*70 -> 1750 | M27: East Carolina | N27: 25 | P27: 0 | Q27: Freshman | R27: 1
G28: 72 | H28: 2 | J28: Eastern Michigan | K28: 26 | L28: =K28*70 -> 1820 | M28: Eastern Michigan | N28: 26 | P28: 1 | Q28: Sophomore | R28: 2
G29: 71 | H29: 2 | J29: Florida | K29: 27 | L29: =K29*70 -> 1890 | M29: Florida | N29: 27 | P29: 2 | Q29: Junior | R29: 3
G30: 70 | H30: 1 | J30: Florida State | K30: 28 | L30: =K30*70 -> 1960 | M30: Florida State | N30: 28 | P30: 3 | Q30: Senior | R30: 4
G31: 69 | H31: 1 | J31: Fresno State | K31: 29 | L31: =K31*70 -> 2030 | M31: Fresno State | N31: 29
G32: 68 | H32: 1 | J32: Georgia | K32: 30 | L32: =K32*70 -> 2100 | M32: Georgia | N32: 30
J33: Georgia Tech | K33: 31 | L33: =K33*70 -> 2170 | M33: Georgia Tech | N33: 31
J34: Hawaii | K34: 32 | L34: =K34*70 -> 2240 | M34: Hawaii | N34: 32
J35: Houston | K35: 33 | L35: =K35*70 -> 2310 | M35: Houston | N35: 33
J36: Idaho | K36: 34 | L36: =K36*70 -> 2380 | M36: Idaho | N36: 34
J37: Illinois | K37: 35 | L37: =K37*70 -> 2450 | M37: Illinois | N37: 35
J38: Indiana | K38: 36 | L38: =K38*70 -> 2520 | M38: Indiana | N38: 36
J39: Iowa | K39: 37 | L39: =K39*70 -> 2590 | M39: Iowa | N39: 37
J40: Iowa State | K40: 38 | L40: =K40*70 -> 2660 | M40: Iowa State | N40: 38
J41: Kansas | K41: 39 | L41: =K41*70 -> 2730 | M41: Kansas | N41: 39
J42: Kansas State | K42: 40 | L42: =K42*70 -> 2800 | M42: Kansas State | N42: 40
...

Sheet Teams
A1: Boston College | B1: BC | C1: ACC | D1: 65
A2: Clemson | B2: CLEM | C2: ACC | D2: 85
A3: Duke | B3: DUKE | C3: ACC | D3: 50
A4: Florida State | B4: FSU | C4: ACC | D4: 65
A5: Georgia Tech | B5: GT | C5: ACC | D5: 55
A6: Louisville | B6: LOUI | C6: ACC | D6: 62
A7: Miami | B7: MIA | C7: ACC | D7: 70
A8: North Carolina | B8: UNC | C8: ACC | D8: 50
A9: NC State | B9: NCST | C9: ACC | D9: 65
A10: Pittsburgh | B10: PITT | C10: ACC | D10: 64
A11: Syracuse | B11: SYR | C11: ACC | D11: 62
A12: Wake Forest | B12: WAKE | C12: ACC | D12: 65
... A14: Virginia Tech | B14: VTEC | C14: ACC | D14: 65
A15: [END_CONF]
A16: Illinois | B16: ILL | C16: Big Ten | D16: 50
A17: Indiana | B17: IND | C17: Big Ten | D17: 50
A18: Iowa | B18: IOW | C18: Big Ten | D18: 65
A19: Maryland | B19: MARY | C19: Big Ten | D19: 53
A20: Michigan | B20: MIC | C20: Big Ten | D20: 80
A21: Michigan State | B21: MSU | C21: Big Ten | D21: 75
A22: Minnesota | B22: MIN | C22: Big Ten | D22: 63
A23: Nebraska | B23: NEB | C23: Big Ten | D23: 60
A24: Northwestern | B24: NWU | C24: Big Ten | D24: 60
A25: Ohio State | B25: OSU | C25: Big Ten | D25: 85
A26: Penn State | B26: PSU | C26: Big Ten | D26: 75
A27: Purdue | B27: PUR | C27: Big Ten | D27: 50
... A29: Wisconsin | B29: WIS | C29: Big Ten | D29: 70
A30: [END_CONF]
A31: Baylor | B31: BAY | C31: Big 12 | D31: 65
A32: Iowa State | B32: ISU | C32: Big 12 | D32: 65
A33: Texas Tech | B33: TTEC | C33: Big 12 | D33: 55
A34: Kansas | B34: KAN | C34: Big 12 | D34: 50
A35: Kansas State | B35: KSU | C35: Big 12 | D35: 58
A36: Oklahoma | B36: OKL | C36: Big 12 | D36: 85
A37: Oklahoma State | B37: OKST | C37: Big 12 | D37: 73
A38: Texas | B38: TEX | C38: Big 12 | D38: 73
A39: TCU | B39: TCU | C39: Big 12 | D39: 67
A40: West Virginia | B40: WVU | C40: Big 12 | D40: 66
A41: [END_CONF]
A42: Arizona | B42: ARIZ | C42: Pac-12 | D42: 50
...
